Workbook

Sheet Chart of Accounts ERPNext
A1: BAGAN AKUN (CHART OF ACCOUNTS) INDUSTRI MANUFAKTUR - ERPNEXT
A2: Format Standar Siap Import ke ERPNext (Accounting > Chart of Accounts Importer / Data Import)
A4: Account Code (Kode Akun) | B4: Account Name (Nama Akun) | C4: Parent Account Code (Kode Induk) | D4: Parent Account Name (Nama Akun Induk) | E4: Root Type (Kategori Utama) | F4: Is Group (1=Induk, 0=Transaksi) | G4: Account Type (Tipe Akun ERPNext) | H4: Kategori Manufaktur (Fungsi Operasional) | I4: Keterangan / Fungsi Akun
A5: 1000 | B5: ASET | E5: Asset | F5: 1 | H5: Header Utama | I5: Induk utama seluruh aset perusahaan manufaktur
A6: 1100 | B6: Aset Lancar | C6: 1000 | D6: ASET | E6: Asset | F6: 1 | H6: Aset Lancar | I6: Kelompok aset cair dan operasional jangka pendek (<1 tahun)
A7: 1110 | B7: Kas & Bank | C7: 1100 | D7: Aset Lancar | E7: Asset | F7: 1 | G7: Bank | H7: Kas & Bank | I7: Kelompok seluruh rekening kas tunai dan bank
A8: 1111 | B8: Kas Utama Pabrik | C8: 1110 | D8: Kas & Bank | E8: Asset | F8: 0 | G8: Cash | H8: Kas & Bank | I8: Kas tunai untuk operasional harian pabrik
A9: 1112 | B9: Kas Kecil (Petty Cash) | C9: 1110 | D9: Kas & Bank | E9: Asset | F9: 0 | G9: Cash | H9: Kas & Bank | I9: Kas kecil pengeluaran operasional darurat
A10: 1113 | B10: Bank Mandiri Operasional | C10: 1110 | D10: Kas & Bank | E10: Asset | F10: 0 | G10: Bank | H10: Kas & Bank | I10: Rekening penerimaan pelanggan & pembayaran vendor
A11: 1114 | B11: Bank BCA Operasional | C11: 1110 | D11: Kas & Bank | E11: Asset | F11: 0 | G11: Bank | H11: Kas & Bank | I11: Rekening penggajian (payroll) & utilitas pabrik
A12: 1120 | B12: Piutang Usaha & Lainnya | C12: 1100 | D12: Aset Lancar | E12: Asset | F12: 1 | G12: Receivable | H12: Piutang | I12: Kelompok piutang pelanggan dan karyawan
A13: 1121 | B13: Piutang Usaha (Dagang) | C13: 1120 | D13: Piutang Usaha & Lainnya | E13: Asset | F13: 0 | G13: Receivable | H13: Piutang | I13: Terikat otomatis ke Sales Invoice Pelanggan (Customer)
A14: 1122 | B14: Cadangan Kerugian Piutang | C14: 1120 | D14: Piutang Usaha & Lainnya | E14: Asset | F14: 0 | G14: Receivable | H14: Piutang | I14: Akun kontra piutang tak tertagih
A15: 1123 | B15: Piutang Karyawan & Kasbon | C15: 1120 | D15: Piutang Usaha & Lainnya | E15: Asset | F15: 0 | G15: Receivable | H15: Piutang | I15: Pinjaman/kasbon sementara staf & buruh pabrik
A16: 1130 | B16: Persediaan (Stock) | C16: 1100 | D16: Aset Lancar | E16: Asset | F16: 1 | G16: Stock | H16: Persediaan Manufaktur | I16: Kelompok persediaan bahan & barang manufaktur
A17: 1131 | B17: Persediaan Bahan Baku (Raw Materials) | C17: 1130 | D17: Persediaan (Stock) | E17: Asset | F17: 0 | G17: Stock | H17: Bahan Baku | I17: Nilai fisik bahan baku utama produksi
A18: 1132 | B18: Persediaan Bahan Penolong (Auxiliary Materials) | C18: 1130 | D18: Persediaan (Stock) | E18: Asset | F18: 0 | G18: Stock | H18: Bahan Penolong | I18: Nilai bahan pelengkap/kimia/perekat produksi
... A23: 1137 | B23: Barang Dalam Perjalanan (Stock In Transit) | C23: 1130 | D23: Persediaan (Stock) | E23: Asset | F23: 0 | G23: Stock | H23: Stock In Transit | I23: Stok bahan baku/barang yang sedang dalam pengiriman
A24: 1140 | B24: Uang Muka & Biaya Dibayar Muka | C24: 1100 | D24: Aset Lancar | E24: Asset | F24: 1 | H24: Uang Muka | I24: Pembayaran di awal untuk vendor/sewa/pajak
A25: 1141 | B25: Uang Muka Pembelian Bahan Baku | C25: 1140 | D25: Uang Muka & Biaya Dibayar Muka | E25: Asset | F25: 0 | G25: Payable | H25: Uang Muka Vendor | I25: DP/Uang muka pembelian ke supplier bahan baku
A26: 1142 | B26: Uang Muka Sewa Gedung Pabrik | C26: 1140 | D26: Uang Muka & Biaya Dibayar Muka | E26: Asset | F26: 0 | H26: Uang Muka Sewa | I26: Sewa gedung/lahan pabrik dibayar di muka
A27: 1143 | B27: Uang Muka Asuransi Mesin & Pabrik | C27: 1140 | D27: Uang Muka & Biaya Dibayar Muka | E27: Asset | F27: 0 | H27: Uang Muka Asuransi | I27: Asuransi kebakaran/mesin dibayar di muka
A28: 1144 | B28: PPN Masukan (Input VAT) | C28: 1140 | D28: Uang Muka & Biaya Dibayar Muka | E28: Asset | F28: 0 | G28: Tax | H28: Pajak Masukan | I28: PPN 11% atas pembelian bahan baku & jasa
A29: 1200 | B29: Aset Tetap (Fixed Assets) | C29: 1000 | D29: ASET | E29: Asset | F29: 1 | G29: Fixed Asset | H29: Aset Tetap | I29: Induk seluruh aset tetap pabrik & kantor
A30: 1210 | B30: Tanah & Bangunan Pabrik | C30: 1200 | D30: Aset Tetap (Fixed Assets) | E30: Asset | F30: 1 | G30: Fixed Asset | H30: Infrastruktur Pabrik | I30: Infrastruktur tanah & gedung pabrik
A31: 1211 | B31: Tanah Pabrik | C31: 1210 | D31: Tanah & Bangunan Pabrik | E31: Asset | F31: 0 | G31: Fixed Asset | H31: Infrastruktur Pabrik | I31: Nilai perolehan tanah pabrik & pergudangan
A32: 1212 | B32: Bangunan & Gedung Pabrik | C32: 1210 | D32: Tanah & Bangunan Pabrik | E32: Asset | F32: 0 | G32: Fixed Asset | H32: Infrastruktur Pabrik | I32: Nilai perolehan gedung pabrik & gudang
A33: 1213 | B33: Akum. Penyusutan Bangunan Pabrik | C33: 1210 | D33: Tanah & Bangunan Pabrik | E33: Asset | F33: 0 | G33: Accumulated Depreciation | H33: Penyusutan | I33: Akumulasi depresiasi gedung pabrik (kontra aset)
A34: 1220 | B34: Mesin & Peralatan Produksi | C34: 1200 | D34: Aset Tetap (Fixed Assets) | E34: Asset | F34: 1 | G34: Fixed Asset | H34: Mesin Produksi | I34: Seluruh lini mesin produksi manufaktur
A35: 1221 | B35: Mesin Produksi & Lini Perakitan | C35: 1220 | D35: Mesin & Peralatan Produksi | E35: Asset | F35: 0 | G35: Fixed Asset | H35: Mesin Produksi | I35: Nilai perolehan mesin CNC, cetak, potong, dll.
A36: 1222 | B36: Akum. Penyusutan Mesin Produksi | C36: 1220 | D36: Mesin & Peralatan Produksi | E36: Asset | F36: 0 | G36: Accumulated Depreciation | H36: Penyusutan | I36: Akumulasi depresiasi mesin pabrik
A37: 1223 | B37: Alat Berat & Forklift Pabrik | C37: 1220 | D37: Mesin & Peralatan Produksi | E37: Asset | F37: 0 | G37: Fixed Asset | H37: Alat Berat Pabrik | I37: Nilai perolehan forklift, loader, crane pabrik
A38: 1224 | B38: Akum. Penyusutan Alat Berat | C38: 1220 | D38: Mesin & Peralatan Produksi | E38: Asset | F38: 0 | G38: Accumulated Depreciation | H38: Penyusutan | I38: Akumulasi depresiasi alat berat pabrik
A39: 1230 | B39: Inventaris & IT Kantor | C39: 1200 | D39: Aset Tetap (Fixed Assets) | E39: Asset | F39: 1 | G39: Fixed Asset | H39: Aset Kantor | I39: Peralatan pendukung kantor & sistem IT
... A41: 1232 | B41: Akum. Penyusutan Peralatan Kantor | C41: 1230 | D41: Inventaris & IT Kantor | E41: Asset | F41: 0 | G41: Accumulated Depreciation | H41: Penyusutan | I41: Akumulasi depresiasi peralatan kantor
A42: 2000 | B42: KEWAJIBAN (LIABILITAS) | E42: Liability | F42: 1 | H42: Header Utama | I42: Induk utama seluruh hutang & kewajiban
A43: 2100 | B43: Kewajiban Jangka Pendek | C43: 2000 | D43: KEWAJIBAN (LIABILITAS) | E43: Liability | F43: 1 | H43: Hutang Lancar | I43: Kewajiban yang harus dilunasi dalam <1 tahun
A44: 2110 | B44: Hutang Usaha & Pengadaan | C44: 2100 | D44: Kewajiban Jangka Pendek | E44: Liability | F44: 1 | G44: Payable | H44: Hutang Usaha | I44: Kelompok hutang ke supplier & subkontraktor
A45: 2111 | B45: Hutang Dagang (Pemasok Bahan Baku) | C45: 2110 | D45: Hutang Usaha & Pengadaan | E45: Liability | F45: 0 | G45: Payable | H45: Hutang Bahan Baku | I45: Terikat otomatis ke Purchase Invoice Supplier
A46: 2112 | B46: Hutang Jasa Makloon (Subkontrak) | C46: 2110 | D46: Hutang Usaha & Pengadaan | E46: Liability | F46: 0 | G46: Payable | H46: Hutang Makloon | I46: Hutang atas pekerjaan produksi yang di-subkontrakkan
...

Sheet Petunjuk Import ERPNext
A1: PANDUAN IMPOR BAGAN AKUN KE ERPNEXT
A2: Langkah-langkah Praktis Mengunggah File ke Sistem ERPNext
A4: Langkah 1: Persiapan Perusahaan (Company)
A5: 1. Pastikan Perusahaan (Company) Anda sudah dibuat di ERPNext (Setup > Company).
A6: 2. Jika membuat Perusahaan baru, Anda bisa memilih opsi 'Chart of Accounts Importer' agar struktur bawaan kosong/bersih.
A8: Langkah 2: Menggunakan Chart of Accounts Importer di ERPNext
A9: 1. Masuk ke modul Accounting > Chart of Accounts Importer.
A10: 2. Pilih nama Perusahaan Anda pada kolom Company.
A11: 3. Ekspor/Simpan Tab 'Chart of Accounts ERPNext' dari file Excel ini menjadi format .CSV atau langsung Upload file .XLSX ini.
A12: 4. Petakan (Map) kolom Excel ke field ERPNext berikut:
A13: - Account Code -> Account Number / Code
A14: - Account Name -> Account Name
... A32: 5. Set Default Operating Cost Account = 5400 (Biaya Overhead Pabrik).

Sheet Ringkasan Struktur Akun
A1: RINGKASAN REKAPITULASI KODE AKUN MANUFAKTUR
A2: Distribusi Kelompok Akun dan Statistik Pemetaan ERPNext
A4: Kode Head | B4: Kategori Utama (Root Type) | C4: Jumlah Akun Induk (Group) | D4: Jumlah Akun Transaksi (Ledger) | E4: Total Akun | F4: Fokus Utama Manufaktur
A5: 1000 | B5: ASET (Assets) | C5: =COUNTIFS('Chart of Accounts ERPNext'!E5:E100, "Asset", 'Chart of Accounts ERPNext'!F5:F100, 1) | D5: =COUNTIFS('Chart of Accounts ERPNext'!E5:E100, "Asset", 'Chart of Accounts ERPNext'!F5:F100, 0) | E5: =SUM(C5:D5) | F5: Bahan Baku, WIP, Barang Jadi, Spareparts & Mesin Produksi
A6: 2000 | B6: KEWAJIBAN (Liabilities) | C6: =COUNTIFS('Chart of Accounts ERPNext'!E5:E100, "Liability", 'Chart of Accounts ERPNext'!F5:F100, 1) | D6: =COUNTIFS('Chart of Accounts ERPNext'!E5:E100, "Liability", 'Chart of Accounts ERPNext'!F5:F100, 0) | E6: =SUM(C6:D6) | F6: Hutang Supplier Bahan Baku, Makloon & Akrual Buruh
A7: 3000 | B7: EKUITAS (Equity) | C7: =COUNTIFS('Chart of Accounts ERPNext'!E5:E100, "Equity", 'Chart of Accounts ERPNext'!F5:F100, 1) | D7: =COUNTIFS('Chart of Accounts ERPNext'!E5:E100, "Equity", 'Chart of Accounts ERPNext'!F5:F100, 0) | E7: =SUM(C7:D7) | F7: Modal Disetor, Laba Ditahan & Clearing Adjust Stok
A8: 4000 | B8: PENDAPATAN (Income) | C8: =COUNTIFS('Chart of Accounts ERPNext'!E5:E100, "Income", 'Chart of Accounts ERPNext'!F5:F100, 1) | D8: =COUNTIFS('Chart of Accounts ERPNext'!E5:E100, "Income", 'Chart of Accounts ERPNext'!F5:F100, 0) | E8: =SUM(C8:D8) | F8: Penjualan Produk Manufaktur, Jasa Makloon & Scrap
A9: 5000 | B9: HPP & BIAYA PRODUKSI (Expense) | C9: =COUNTIFS('Chart of Accounts ERPNext'!E5:E100, "Expense", 'Chart of Accounts ERPNext'!A5:A100, "5*", 'Chart of Accounts ERPNext'!F5:F100, 1) | D9: =COUNTIFS('Chart of Accounts ERPNext'!E5:E100, "Expense", 'Chart of Accounts ERPNext'!A5:A100, "5*", 'Chart of Accounts ERPNext'!F5:F100, 0) | E9: =SUM(C9:D9) | F9: Biaya Bahan Langsung, Upah Buruh & Overhead Pabrik (BOP)
A10: 6000 | B10: BEBAN OPERASIONAL (Expense) | C10: =COUNTIFS('Chart of Accounts ERPNext'!E5:E100, "Expense", 'Chart of Accounts ERPNext'!A5:A100, "6*", 'Chart of Accounts ERPNext'!F5:F100, 1) | D10: =COUNTIFS('Chart of Accounts ERPNext'!E5:E100, "Expense", 'Chart of Accounts ERPNext'!A5:A100, "6*", 'Chart of Accounts ERPNext'!F5:F100, 0) | E10: =SUM(C10:D10) | F10: Beban Pengiriman (Freight Out), Sales & Umum Admin
B11: TOTAL KELOMPOK AKUN | C11: =SUM(C5:C10) | D11: =SUM(D5:D10) | E11: =SUM(E5:E10) | F11: Struktur Lengkap Kompatibel dengan ERPNext v14/v15/v16
